Workbook

Sheet Sheet1
A1: STT | B1: NgayHoaDon | C1: MaKhachHang | D1: TenKhachHang | E1: TenNguoiMua | F1: MaSoThue | G1: DiaChiKhachHang | H1: DienThoaiKhachHang | I1: SoTaiKhoan | J1: NganHang | K1: HinhThucTT | L1: MaSanPham | M1: SanPham | N1: DonViTinh | O1: Extra1SP | P1: Extra2SP | Q1: SoLuong | R1: DonGia | S1: TyLeChietKhau | T1: SoTienChietKhau | U1: ThanhTien | V1: TienBan | W1: ThueSuat | X1: TienThueSanPham | Y1: TienThue | Z1: TongCong | AA1: TinhChatHangHoa | AB1: DonViTienTe | AC1: TyGia | AD1: Fkey | AE1: Extra1 | AF1: Extra2 | AG1: EmailKhachHang | AH1: VungDuLieu | AI1: Extra3 | AJ1: Extra4 | AK1: Extra5 | AL1: Extra6 | AM1: Extra7 | AN1: Extra8 | AO1: Extra9 | AP1: Extra10 | AQ1: Extra11 | AR1: Extra12 | AS1: LDDNBo | AT1: HDSo | AU1: HVTNXHang | AV1: TNVChuyen | AW1: PTVChuyen | AX1: HDKTNgay | AY1: HDKTSo | AZ1: CCCDan | BC1: mau_01
C2: =+'S3'!AB2 -> BBLANH | D2: =+IFERROR(VLOOKUP(F2,Sheet2!F:G,2,0),"") -> CÔNG TY TNHH SANH LÀNH | E2: =+IFERROR(VLOOKUP(C2,'S3'!E:F,2,0),"") -> CÔNG TY TNHH SANH LàNH | F2: =+IFERROR(VLOOKUP(C2,Sheet2!C:F,4,0),"") -> 0901190846 | G2: =+IFERROR(VLOOKUP(F2,Sheet2!F:H,3,0),"") -> Thôn Đồng Chung, Xã Đại Đồng, Tỉnh Hưng Yên, Việt Nam | K2: =+'S3'!AC2 -> TM/CK | L2: =IF('S3'!J2<>"",'S3'!J2,"") -> 68477297 | M2: =IF('S3'!K2<>"",'S3'!K2,"") -> CLEAR dầu gội mát lạnh bạc hà 630g/8 chai | N2: =+IFERROR(VLOOKUP(L2,Sheet3!A:C,3,0)," ") -> Chai | Q2: =+'S3'!N2 -> 80 | R2: =+'S3'!T2 -> 136500 | U2: =+R2*Q2 -> 10920000 | V2: =+'S3'!X2 -> 94400037 | W2: =+'S3'!Y2 -> 8 | Y2: =IFERROR(W2%*V2,"") -> 7552003 | Z2: =IFERROR(ROUND(V2+Y2,0),"") -> 101952040 | AA2: 0 | AB2: =+'S3'!Z2 -> VND
C3: =+'S3'!AB3 | D3: =+IFERROR(VLOOKUP(F3,Sheet2!F:G,2,0),"") | E3: =+IFERROR(VLOOKUP(C3,'S3'!E:F,2,0),"") | F3: =+IFERROR(VLOOKUP(C3,Sheet2!C:F,4,0),"") | G3: =+IFERROR(VLOOKUP(F3,Sheet2!F:H,3,0),"") | K3: =+'S3'!AC3 | L3: =IF('S3'!J3<>"",'S3'!J3,"") -> 68942958 | M3: =IF('S3'!K3<>"",'S3'!K3,"") -> CLEAR MEN Dầu Gội Mát Lạnh Bạc Hà 630g/8 Chai | N3: =+IFERROR(VLOOKUP(L3,Sheet3!A:C,3,0)," ") -> CHAI | Q3: =+'S3'!N3 -> 80 | R3: =+'S3'!T3 -> 131318.52 | U3: =+R3*Q3 -> 10505481 | V3: =+'S3'!X3 | W3: =+'S3'!Y3 | Y3: =IFERROR(W3%*V3,"") | Z3: =IFERROR(ROUND(V3+Y3,0),"") | AA3: 0 | AB3: =+'S3'!Z3
C4: =+'S3'!AB4 | D4: =+IFERROR(VLOOKUP(F4,Sheet2!F:G,2,0),"") | E4: =+IFERROR(VLOOKUP(C4,'S3'!E:F,2,0),"") | F4: =+IFERROR(VLOOKUP(C4,Sheet2!C:F,4,0),"") | G4: =+IFERROR(VLOOKUP(F4,Sheet2!F:H,3,0),"") | K4: =+'S3'!AC4 | L4: =IF('S3'!J4<>"",'S3'!J4,"") -> 65647167 | M4: =IF('S3'!K4<>"",'S3'!K4,"") -> DOVE Dầu Gội CERAMIDE Phục Hồi Hư Tổn 600G/8 Chai | N4: =+IFERROR(VLOOKUP(L4,Sheet3!A:C,3,0)," ") -> chai | Q4: =+'S3'!N4 -> 80 | R4: =+'S3'!T4 -> 117425.93 | U4: =+R4*Q4 -> 9394074.1 | V4: =+'S3'!X4 | W4: =+'S3'!Y4 | Y4: =IFERROR(W4%*V4,"") | Z4: =IFERROR(ROUND(V4+Y4,0),"") | AA4: 0 | AB4: =+'S3'!Z4
C5: =+'S3'!AB5 | D5: =+IFERROR(VLOOKUP(F5,Sheet2!F:G,2,0),"") | E5: =+IFERROR(VLOOKUP(C5,'S3'!E:F,2,0),"") | F5: =+IFERROR(VLOOKUP(C5,Sheet2!C:F,4,0),"") | G5: =+IFERROR(VLOOKUP(F5,Sheet2!F:H,3,0),"") | K5: =+'S3'!AC5 | L5: =IF('S3'!J5<>"",'S3'!J5,"") -> 65484984 | M5: =IF('S3'!K5<>"",'S3'!K5,"") -> SUNSILK Dầu Gội Mềm Mượt Diệu Kỳ 600G/8 Chai | N5: =+IFERROR(VLOOKUP(L5,Sheet3!A:C,3,0)," ") -> chai | Q5: =+'S3'!N5 -> 80 | R5: =+'S3'!T5 -> 104662.96 | U5: =+R5*Q5 -> 8373037 | V5: =+'S3'!X5 | W5: =+'S3'!Y5 | Y5: =IFERROR(W5%*V5,"") | Z5: =IFERROR(ROUND(V5+Y5,0),"") | AA5: 0 | AB5: =+'S3'!Z5
C6: =+'S3'!AB6 | D6: =+IFERROR(VLOOKUP(F6,Sheet2!F:G,2,0),"") | E6: =+IFERROR(VLOOKUP(C6,'S3'!E:F,2,0),"") | F6: =+IFERROR(VLOOKUP(C6,Sheet2!C:F,4,0),"") | G6: =+IFERROR(VLOOKUP(F6,Sheet2!F:H,3,0),"") | K6: =+'S3'!AC6 | L6: =IF('S3'!J6<>"",'S3'!J6,"") -> 68181864 | M6: =IF('S3'!K6<>"",'S3'!K6,"") -> CLOSEUP KĐR Tinh Thể Băng Tuyết 180g/36 ống | N6: =+IFERROR(VLOOKUP(L6,Sheet3!A:C,3,0)," ") -> Tuyp | Q6: =+'S3'!N6 -> 360 | R6: =+'S3'!T6 -> 29225 | U6: =+R6*Q6 -> 10521000 | V6: =+'S3'!X6 | W6: =+'S3'!Y6 | Y6: =IFERROR(W6%*V6,"") | Z6: =IFERROR(ROUND(V6+Y6,0),"") | AA6: 0 | AB6: =+'S3'!Z6
C7: =+'S3'!AB7 | D7: =+IFERROR(VLOOKUP(F7,Sheet2!F:G,2,0),"") | E7: =+IFERROR(VLOOKUP(C7,'S3'!E:F,2,0),"") | F7: =+IFERROR(VLOOKUP(C7,Sheet2!C:F,4,0),"") | G7: =+IFERROR(VLOOKUP(F7,Sheet2!F:H,3,0),"") | K7: =+'S3'!AC7 | L7: =IF('S3'!J7<>"",'S3'!J7,"") -> 62758282 | M7: =IF('S3'!K7<>"",'S3'!K7,"") -> CLOSEUP KĐR Bạc Hà Thơm Mát 180g/36 ống | N7: =+IFERROR(VLOOKUP(L7,Sheet3!A:C,3,0)," ") -> ống | Q7: =+'S3'!N7 -> 360 | R7: =+'S3'!T7 -> 29225 | U7: =+R7*Q7 -> 10521000 | V7: =+'S3'!X7 | W7: =+'S3'!Y7 | Y7: =IFERROR(W7%*V7,"") | Z7: =IFERROR(ROUND(V7+Y7,0),"") | AA7: 0 | AB7: =+'S3'!Z7
C8: =+'S3'!AB8 | D8: =+IFERROR(VLOOKUP(F8,Sheet2!F:G,2,0),"") | E8: =+IFERROR(VLOOKUP(C8,'S3'!E:F,2,0),"") | F8: =+IFERROR(VLOOKUP(C8,Sheet2!C:F,4,0),"") | G8: =+IFERROR(VLOOKUP(F8,Sheet2!F:H,3,0),"") | K8: =+'S3'!AC8 | L8: =IF('S3'!J8<>"",'S3'!J8,"") -> 65591283 | M8: =IF('S3'!K8<>"",'S3'!K8,"") -> P/S KĐR Trắng Răng Than Hoạt Tính & Tre 180g/36 ống | N8: =+IFERROR(VLOOKUP(L8,Sheet3!A:C,3,0)," ") -> ống | Q8: =+'S3'!N8 -> 180 | R8: =+'S3'!T8 -> 28206.481 | U8: =+R8*Q8 -> 5077166.7 | V8: =+'S3'!X8 | W8: =+'S3'!Y8 | Y8: =IFERROR(W8%*V8,"") | Z8: =IFERROR(ROUND(V8+Y8,0),"") | AA8: 0 | AB8: =+'S3'!Z8
C9: =+'S3'!AB9 | D9: =+IFERROR(VLOOKUP(F9,Sheet2!F:G,2,0),"") | E9: =+IFERROR(VLOOKUP(C9,'S3'!E:F,2,0),"") | F9: =+IFERROR(VLOOKUP(C9,Sheet2!C:F,4,0),"") | G9: =+IFERROR(VLOOKUP(F9,Sheet2!F:H,3,0),"") | K9: =+'S3'!AC9 | L9: =IF('S3'!J9<>"",'S3'!J9,"") -> 65591284 | M9: =IF('S3'!K9<>"",'S3'!K9,"") -> P/S KĐR Ngừa Sâu Răng Vượt Trội 180g/36 ống | N9: =+IFERROR(VLOOKUP(L9,Sheet3!A:C,3,0)," ") -> ống | Q9: =+'S3'!N9 -> 360 | R9: =+'S3'!T9 -> 21953.704 | U9: =+R9*Q9 -> 7903333.3 | V9: =+'S3'!X9 | W9: =+'S3'!Y9 | Y9: =IFERROR(W9%*V9,"") | Z9: =IFERROR(ROUND(V9+Y9,0),"") | AA9: 0 | AB9: =+'S3'!Z9
C10: =+'S3'!AB10 | D10: =+IFERROR(VLOOKUP(F10,Sheet2!F:G,2,0),"") | E10: =+IFERROR(VLOOKUP(C10,'S3'!E:F,2,0),"") | F10: =+IFERROR(VLOOKUP(C10,Sheet2!C:F,4,0),"") | G10: =+IFERROR(VLOOKUP(F10,Sheet2!F:H,3,0),"") | K10: =+'S3'!AC10 | L10: =IF('S3'!J10<>"",'S3'!J10,"") -> 65591301 | M10: =IF('S3'!K10<>"",'S3'!K10,"") -> P/S KĐR Ngừa Sâu Răng Vượt Trội 100g/60 ống | N10: =+IFERROR(VLOOKUP(L10,Sheet3!A:C,3,0)," ") -> ống | Q10: =+'S3'!N10 -> 600 | R10: =+'S3'!T10 -> 13415.741 | U10: =+R10*Q10 -> 8049444.4 | V10: =+'S3'!X10 | W10: =+'S3'!Y10 | Y10: =IFERROR(W10%*V10,"") | Z10: =IFERROR(ROUND(V10+Y10,0),"") | AA10: 0 | AB10: =+'S3'!Z10
C11: =+'S3'!AB11 | D11: =+IFERROR(VLOOKUP(F11,Sheet2!F:G,2,0),"") | E11: =+IFERROR(VLOOKUP(C11,'S3'!E:F,2,0),"") | F11: =+IFERROR(VLOOKUP(C11,Sheet2!C:F,4,0),"") | G11: =+IFERROR(VLOOKUP(F11,Sheet2!F:H,3,0),"") | K11: =+'S3'!AC11 | L11: =IF('S3'!J11<>"",'S3'!J11,"") -> 65251314 | M11: =IF('S3'!K11<>"",'S3'!K11,"") -> KNORR Hạt Nêm Từ Thịt 1.8kg/6 gói | N11: =+IFERROR(VLOOKUP(L11,Sheet3!A:C,3,0)," ") -> gói | Q11: =+'S3'!N11 -> 60 | R11: =+'S3'!T11 -> 77258.333 | U11: =+R11*Q11 -> 4635500 | V11: =+'S3'!X11 | W11: =+'S3'!Y11 | Y11: =IFERROR(W11%*V11,"") | Z11: =IFERROR(ROUND(V11+Y11,0),"") | AA11: 0 | AB11: =+'S3'!Z11
C12: =+'S3'!AB12 | D12: =+IFERROR(VLOOKUP(F12,Sheet2!F:G,2,0),"") | E12: =+IFERROR(VLOOKUP(C12,'S3'!E:F,2,0),"") | F12: =+IFERROR(VLOOKUP(C12,Sheet2!C:F,4,0),"") | G12: =+IFERROR(VLOOKUP(F12,Sheet2!F:H,3,0),"") | K12: =+'S3'!AC12 | L12: =IF('S3'!J12<>"",'S3'!J12,"") -> 65252542 | M12: =IF('S3'!K12<>"",'S3'!K12,"") -> KNORR Hạt Nêm Từ Thịt 900g/8 gói | N12: =+IFERROR(VLOOKUP(L12,Sheet3!A:C,3,0)," ") -> gói | Q12: =+'S3'!N12 -> 160 | R12: =+'S3'!T12 -> 53125 | U12: =+R12*Q12 -> 8500000 | V12: =+'S3'!X12 | W12: =+'S3'!Y12 | Y12: =IFERROR(W12%*V12,"") | Z12: =IFERROR(ROUND(V12+Y12,0),"") | AA12: 0 | AB12: =+'S3'!Z12
C13: =+'S3'!AB13 | D13: =+IFERROR(VLOOKUP(F13,Sheet2!F:G,2,0),"") | E13: =+IFERROR(VLOOKUP(C13,'S3'!E:F,2,0),"") | F13: =+IFERROR(VLOOKUP(C13,Sheet2!C:F,4,0),"") | G13: =+IFERROR(VLOOKUP(F13,Sheet2!F:H,3,0),"") | K13: =+'S3'!AC13 | L13: =IF('S3'!J13<>"",'S3'!J13,"") | M13: =IF('S3'!K13<>"",'S3'!K13,"") | N13: =+IFERROR(VLOOKUP(L13,Sheet3!A:C,3,0)," ") -> 0 | Q13: =+'S3'!N13 -> 0 | R13: =+'S3'!T13 -> 0 | U13: =+R13*Q13 -> 0 | V13: =+'S3'!X13 | W13: =+'S3'!Y13 | Y13: =IFERROR(W13%*V13,"") | Z13: =IFERROR(ROUND(V13+Y13,0),"") | AA13: 0 | AB13: =+'S3'!Z13
... C388: =+'S3'!AB388 | D388: =+IFERROR(VLOOKUP(F388,Sheet2!F:G,2,0),"") | E388: =+IFERROR(VLOOKUP(C388,'S3'!E:F,2,0),"") | F388: =+IFERROR(VLOOKUP(C388,Sheet2!C:F,4,0),"") | G388: =+IFERROR(VLOOKUP(F388,Sheet2!F:H,3,0),"") | K388: =+'S3'!AC388 | L388: =IF('S3'!J388<>"",'S3'!J388,"") | M388: =IF('S3'!K388<>"",'S3'!K388,"") | N388: =+IFERROR(VLOOKUP(L388,Sheet3!A:C,3,0)," ") -> 0 | Q388: =+'S3'!N388 -> 0 | R388: =+'S3'!T388 -> 0 | U388: =+R388*Q388 -> 0 | V388: =+'S3'!X388 | W388: =+'S3'!Y388 | Y388: =IFERROR(W388%*V388,"") | Z388: =IFERROR(ROUND(V388+Y388,0),"") | AA388: 0 | AB388: =+'S3'!Z388
C389: =+'S3'!AB389 | W389: =+'S3'!Y389 | Y389: =IFERROR(W389%*V389,"") | Z389: =IFERROR(ROUND(V389+Y389,0),"") | AA389: 0 | AB389: =+'S3'!Z389
C390: =+'S3'!AB390
C391: =+'S3'!AB391
C392: =+'S3'!AB392
C393: =+'S3'!AB393
C394: =+'S3'!AB394
C395: =+'S3'!AB395
C396: =+'S3'!AB396
C397: =+'S3'!AB397
C398: =+'S3'!AB398
C399: =+'S3'!AB399
C400: =+'S3'!AB400
C401: =+'S3'!AB401
... C403: =+'S3'!AB403

Sheet S3
A1: Ngày | B1: Số Đơn | C1: Mã Nv | D1: Tên Nv | E1: Mã Khách | F1: Tên Khách | G1: Địa chỉ | H1: Phone | I1: Stt | J1: Mã hàng | K1: Tên hàng | L1: Qc | M1: Là Km | N1: Số lượng | O1: Đơn giá sau KM/Ck | P1: Thành tiền | Q1: Mã Kho | R1: Nhóm hàng | S1: Kênh hàng
A2: 06.07.2026 | B2: B0038982 | C2: BANBUON | D2: Bán Buôn | E2: BBLANH | F2: CÔNG TY TNHH SANH LàNH | I2: 14 | J2: 68477297 | K2: CLEAR dầu gội mát lạnh bạc hà 630g/8 chai | L2: 8 | N2: 80 | O2: 147420 | P2: 11793600 | Q2: KHOCHINH | R2: CLEAR | S2: KHO-PC | T2: =+O2/1.08 -> 136500 | U2: =+T2*N2 -> 10920000 | V2: =+SUMIF(B:B,B2,U:U) -> 94400037 | W2: =+V2 -> 94400037 | X2: =+IF(W2<>0,W2,"") -> 94400037 | Y2: =+IF(X2<>"",8,"") -> 8 | Z2: =+IF(X2<>"","VND","") -> VND | AA2: =+E2 -> BBLANH | AB2: =+IF(AA2<>0,AA2,"") -> BBLANH | AC2: =+IF(X2<>"","TM/CK","") -> TM/CK
A3: 06.07.2026 | B3: B0038982 | C3: BANBUON | D3: Bán Buôn | E3: BBLANH | F3: CÔNG TY TNHH SANH LàNH | I3: 15 | J3: 68942958 | K3: CLEAR MEN Dầu Gội Mát Lạnh Bạc Hà 630g/8 Chai | L3: 8 | N3: 80 | O3: 141824 | P3: 11345920 | Q3: KHOCHINH | R3: CLEAR MEN | S3: KHO-PC | T3: =+O3/1.08 -> 131318.52 | U3: =+T3*N3 -> 10505481 | V3: =+SUMIF(B:B,B3,U:U) -> 94400037 | W3: =+IF(V3=V2,"",V3) | X3: =+IF(W3<>0,W3,"") | Y3: =+IF(X3<>"",8,"") | Z3: =+IF(X3<>"","VND","") | AA3: =+IF(B3=B2,"",E3) | AB3: =+IF(AA3<>0,AA3,"") | AC3: =+IF(X3<>"","TM/CK","")
A4: 06.07.2026 | B4: B0038982 | C4: BANBUON | D4: Bán Buôn | E4: BBLANH | F4: CÔNG TY TNHH SANH LàNH | I4: 16 | J4: 65647167 | K4: DOVE Dầu Gội CERAMIDE Phục Hồi Hư Tổn 600G/8 Chai | L4: 8 | N4: 80 | O4: 126820 | P4: 10145600 | Q4: KHOCHINH | R4: DOVE - Dau goi | S4: KHO-PC | T4: =+O4/1.08 -> 117425.93 | U4: =+T4*N4 -> 9394074.1 | V4: =+SUMIF(B:B,B4,U:U) -> 94400037 | W4: =+IF(V4=V3,"",V4) | X4: =+IF(W4<>0,W4,"") | Y4: =+IF(X4<>"",8,"") | Z4: =+IF(X4<>"","VND","") | AA4: =+IF(B4=B3,"",E4) | AB4: =+IF(AA4<>0,AA4,"") | AC4: =+IF(X4<>"","TM/CK","")
A5: 06.07.2026 | B5: B0038982 | C5: BANBUON | D5: Bán Buôn | E5: BBLANH | F5: CÔNG TY TNHH SANH LàNH | I5: 17 | J5: 65484984 | K5: SUNSILK Dầu Gội Mềm Mượt Diệu Kỳ 600G/8 Chai | L5: 8 | N5: 80 | O5: 113036 | P5: 9042880 | Q5: KHOCHINH | R5: SUNSILK | S5: KHO-PC | T5: =+O5/1.08 -> 104662.96 | U5: =+T5*N5 -> 8373037 | V5: =+SUMIF(B:B,B5,U:U) -> 94400037 | W5: =+IF(V5=V4,"",V5) | X5: =+IF(W5<>0,W5,"") | Y5: =+IF(X5<>"",8,"") | Z5: =+IF(X5<>"","VND","") | AA5: =+IF(B5=B4,"",E5) | AB5: =+IF(AA5<>0,AA5,"") | AC5: =+IF(X5<>"","TM/CK","")
A6: 06.07.2026 | B6: B0038982 | C6: BANBUON | D6: Bán Buôn | E6: BBLANH | F6: CÔNG TY TNHH SANH LàNH | I6: 18 | J6: 68181864 | K6: CLOSEUP KĐR Tinh Thể Băng Tuyết 180g/36 ống | L6: 36 | N6: 360 | O6: 31563 | P6: 11362680 | Q6: KHOCHINH | R6: CLOSE UP | S6: KHO-PC | T6: =+O6/1.08 -> 29225 | U6: =+T6*N6 -> 10521000 | V6: =+SUMIF(B:B,B6,U:U) -> 94400037 | W6: =+IF(V6=V5,"",V6) | X6: =+IF(W6<>0,W6,"") | Y6: =+IF(X6<>"",8,"") | Z6: =+IF(X6<>"","VND","") | AA6: =+IF(B6=B5,"",E6) | AB6: =+IF(AA6<>0,AA6,"") | AC6: =+IF(X6<>"","TM/CK","")
A7: 06.07.2026 | B7: B0038982 | C7: BANBUON | D7: Bán Buôn | E7: BBLANH | F7: CÔNG TY TNHH SANH LàNH | I7: 19 | J7: 62758282 | K7: CLOSEUP KĐR Bạc Hà Thơm Mát 180g/36 ống | L7: 36 | N7: 360 | O7: 31563 | P7: 11362680 | Q7: KHOCHINH | R7: CLOSE UP | S7: KHO-PC | T7: =+O7/1.08 -> 29225 | U7: =+T7*N7 -> 10521000 | V7: =+SUMIF(B:B,B7,U:U) -> 94400037 | W7: =+IF(V7=V6,"",V7) | X7: =+IF(W7<>0,W7,"") | Y7: =+IF(X7<>"",8,"") | Z7: =+IF(X7<>"","VND","") | AA7: =+IF(B7=B6,"",E7) | AB7: =+IF(AA7<>0,AA7,"") | AC7: =+IF(X7<>"","TM/CK","")
A8: 06.07.2026 | B8: B0038982 | C8: BANBUON | D8: Bán Buôn | E8: BBLANH | F8: CÔNG TY TNHH SANH LàNH | I8: 20 | J8: 65591283 | K8: P/S KĐR Trắng Răng Than Hoạt Tính & Tre 180g/36 ống | L8: 36 | N8: 180 | O8: 30463 | P8: 5483340 | Q8: KHOCHINH | R8: P/S | S8: KHO-PC | T8: =+O8/1.08 -> 28206.481 | U8: =+T8*N8 -> 5077166.7 | V8: =+SUMIF(B:B,B8,U:U) -> 94400037 | W8: =+IF(V8=V7,"",V8) | X8: =+IF(W8<>0,W8,"") | Y8: =+IF(X8<>"",8,"") | Z8: =+IF(X8<>"","VND","") | AA8: =+IF(B8=B7,"",E8) | AB8: =+IF(AA8<>0,AA8,"") | AC8: =+IF(X8<>"","TM/CK","")
A9: 06.07.2026 | B9: B0038982 | C9: BANBUON | D9: Bán Buôn | E9: BBLANH | F9: CÔNG TY TNHH SANH LàNH | I9: 21 | J9: 65591284 | K9: P/S KĐR Ngừa Sâu Răng Vượt Trội 180g/36 ống | L9: 36 | N9: 360 | O9: 23710 | P9: 8535600 | Q9: KHOCHINH | R9: P/S | S9: KHO-PC | T9: =+O9/1.08 -> 21953.704 | U9: =+T9*N9 -> 7903333.3 | V9: =+SUMIF(B:B,B9,U:U) -> 94400037 | W9: =+IF(V9=V8,"",V9) | X9: =+IF(W9<>0,W9,"") | Y9: =+IF(X9<>"",8,"") | Z9: =+IF(X9<>"","VND","") | AA9: =+IF(B9=B8,"",E9) | AB9: =+IF(AA9<>0,AA9,"") | AC9: =+IF(X9<>"","TM/CK","")
A10: 06.07.2026 | B10: B0038982 | C10: BANBUON | D10: Bán Buôn | E10: BBLANH | F10: CÔNG TY TNHH SANH LàNH | I10: 22 | J10: 65591301 | K10: P/S KĐR Ngừa Sâu Răng Vượt Trội 100g/60 ống | L10: 60 | N10: 600 | O10: 14489 | P10: 8693400 | Q10: KHOCHINH | R10: P/S | S10: KHO-PC | T10: =+O10/1.08 -> 13415.741 | U10: =+T10*N10 -> 8049444.4 | V10: =+SUMIF(B:B,B10,U:U) -> 94400037 | W10: =+IF(V10=V9,"",V10) | X10: =+IF(W10<>0,W10,"") | Y10: =+IF(X10<>"",8,"") | Z10: =+IF(X10<>"","VND","") | AA10: =+IF(B10=B9,"",E10) | AB10: =+IF(AA10<>0,AA10,"") | AC10: =+IF(X10<>"","TM/CK","")
A11: 06.07.2026 | B11: B0038982 | C11: BANBUON | D11: Bán Buôn | E11: BBLANH | F11: CÔNG TY TNHH SANH LàNH | I11: 24 | J11: 65251314 | K11: KNORR Hạt Nêm Từ Thịt 1.8kg/6 gói | L11: 6 | N11: 60 | O11: 83439 | P11: 5006340 | Q11: KHOCHINH | R11: KNORR | S11: KHO-PC | T11: =+O11/1.08 -> 77258.333 | U11: =+T11*N11 -> 4635500 | V11: =+SUMIF(B:B,B11,U:U) -> 94400037 | W11: =+IF(V11=V10,"",V11) | X11: =+IF(W11<>0,W11,"") | Y11: =+IF(X11<>"",8,"") | Z11: =+IF(X11<>"","VND","") | AA11: =+IF(B11=B10,"",E11) | AB11: =+IF(AA11<>0,AA11,"") | AC11: =+IF(X11<>"","TM/CK","")
A12: 06.07.2026 | B12: B0038982 | C12: BANBUON | D12: Bán Buôn | E12: BBLANH | F12: CÔNG TY TNHH SANH LàNH | I12: 25 | J12: 65252542 | K12: KNORR Hạt Nêm Từ Thịt 900g/8 gói | L12: 8 | N12: 160 | O12: 57375 | P12: 9180000 | Q12: KHOCHINH | R12: KNORR | S12: KHO-PC | T12: =+O12/1.08 -> 53125 | U12: =+T12*N12 -> 8500000 | V12: =+SUMIF(B:B,B12,U:U) -> 94400037 | W12: =+IF(V12=V11,"",V12) | X12: =+IF(W12<>0,W12,"") | Y12: =+IF(X12<>"",8,"") | Z12: =+IF(X12<>"","VND","") | AA12: =+IF(B12=B11,"",E12) | AB12: =+IF(AA12<>0,AA12,"") | AC12: =+IF(X12<>"","TM/CK","")
T13: =+O13/1.08 -> 0 | U13: =+T13*N13 -> 0 | V13: =+SUMIF(B:B,B13,U:U) -> 0 | W13: =+IF(V13=V12,"",V13) -> 0 | X13: =+IF(W13<>0,W13,"") | Y13: =+IF(X13<>"",8,"") | Z13: =+IF(X13<>"","VND","") | AA13: =+IF(B13=B12,"",E13) -> 0 | AB13: =+IF(AA13<>0,AA13,"") | AC13: =+IF(X13<>"","TM/CK","")
T14: =+O14/1.08 -> 0 | U14: =+T14*N14 -> 0 | V14: =+SUMIF(B:B,B14,U:U) -> 0 | W14: =+IF(V14=V13,"",V14) | X14: =+IF(W14<>0,W14,"") | Y14: =+IF(X14<>"",8,"") | Z14: =+IF(X14<>"","VND","") | AA14: =+IF(B14=B13,"",E14) | AB14: =+IF(AA14<>0,AA14,"") | AC14: =+IF(X14<>"","TM/CK","")
T15: =+O15/1.08 -> 0 | U15: =+T15*N15 -> 0 | V15: =+SUMIF(B:B,B15,U:U) -> 0 | W15: =+IF(V15=V14,"",V15) | X15: =+IF(W15<>0,W15,"") | Y15: =+IF(X15<>"",8,"") | Z15: =+IF(X15<>"","VND","") | AA15: =+IF(B15=B14,"",E15) | AB15: =+IF(AA15<>0,AA15,"") | AC15: =+IF(X15<>"","TM/CK","")
T16: =+O16/1.08 -> 0 | U16: =+T16*N16 -> 0 | V16: =+SUMIF(B:B,B16,U:U) -> 0 | W16: =+IF(V16=V15,"",V16) | X16: =+IF(W16<>0,W16,"") | Y16: =+IF(X16<>"",8,"") | Z16: =+IF(X16<>"","VND","") | AA16: =+IF(B16=B15,"",E16) | AB16: =+IF(AA16<>0,AA16,"") | AC16: =+IF(X16<>"","TM/CK","")
T17: =+O17/1.08 -> 0 | U17: =+T17*N17 -> 0 | V17: =+SUMIF(B:B,B17,U:U) -> 0 | W17: =+IF(V17=V16,"",V17) | X17: =+IF(W17<>0,W17,"") | Y17: =+IF(X17<>"",8,"") | Z17: =+IF(X17<>"","VND","") | AA17: =+IF(B17=B16,"",E17) | AB17: =+IF(AA17<>0,AA17,"") | AC17: =+IF(X17<>"","TM/CK","")
T18: =+O18/1.08 -> 0 | U18: =+T18*N18 -> 0 | V18: =+SUMIF(B:B,B18,U:U) -> 0 | W18: =+IF(V18=V17,"",V18) | X18: =+IF(W18<>0,W18,"") | Y18: =+IF(X18<>"",8,"") | Z18: =+IF(X18<>"","VND","") | AA18: =+IF(B18=B17,"",E18) | AB18: =+IF(AA18<>0,AA18,"") | AC18: =+IF(X18<>"","TM/CK","")
T19: =+O19/1.08 -> 0 | U19: =+T19*N19 -> 0 | V19: =+SUMIF(B:B,B19,U:U) -> 0 | W19: =+IF(V19=V18,"",V19) | X19: =+IF(W19<>0,W19,"") | Y19: =+IF(X19<>"",8,"") | Z19: =+IF(X19<>"","VND","") | AA19: =+IF(B19=B18,"",E19) | AB19: =+IF(AA19<>0,AA19,"") | AC19: =+IF(X19<>"","TM/CK","")
T20: =+O20/1.08 -> 0 | U20: =+T20*N20 -> 0 | V20: =+SUMIF(B:B,B20,U:U) -> 0 | W20: =+IF(V20=V19,"",V20) | X20: =+IF(W20<>0,W20,"") | Y20: =+IF(X20<>"",8,"") | Z20: =+IF(X20<>"","VND","") | AA20: =+IF(B20=B19,"",E20) | AB20: =+IF(AA20<>0,AA20,"") | AC20: =+IF(X20<>"","TM/CK","")
T21: =+O21/1.08 -> 0 | U21: =+T21*N21 -> 0 | V21: =+SUMIF(B:B,B21,U:U) -> 0 | W21: =+IF(V21=V20,"",V21) | X21: =+IF(W21<>0,W21,"") | Y21: =+IF(X21<>"",8,"") | Z21: =+IF(X21<>"","VND","") | AA21: =+IF(B21=B20,"",E21) | AB21: =+IF(AA21<>0,AA21,"") | AC21: =+IF(X21<>"","TM/CK","")
T22: =+O22/1.08 -> 0 | U22: =+T22*N22 -> 0 | V22: =+SUMIF(B:B,B22,U:U) -> 0 | W22: =+IF(V22=V21,"",V22) | X22: =+IF(W22<>0,W22,"") | Y22: =+IF(X22<>"",8,"") | Z22: =+IF(X22<>"","VND","") | AA22: =+IF(B22=B21,"",E22) | AB22: =+IF(AA22<>0,AA22,"") | AC22: =+IF(X22<>"","TM/CK","")
T23: =+O23/1.08 -> 0 | U23: =+T23*N23 -> 0 | V23: =+SUMIF(B:B,B23,U:U) -> 0 | W23: =+IF(V23=V22,"",V23) | X23: =+IF(W23<>0,W23,"") | Y23: =+IF(X23<>"",8,"") | Z23: =+IF(X23<>"","VND","") | AA23: =+IF(B23=B22,"",E23) | AB23: =+IF(AA23<>0,AA23,"") | AC23: =+IF(X23<>"","TM/CK","")
T24: =+O24/1.08 -> 0 | U24: =+T24*N24 -> 0 | V24: =+SUMIF(B:B,B24,U:U) -> 0 | W24: =+IF(V24=V23,"",V24) | X24: =+IF(W24<>0,W24,"") | Y24: =+IF(X24<>"",8,"") | Z24: =+IF(X24<>"","VND","") | AA24: =+IF(B24=B23,"",E24) | AB24: =+IF(AA24<>0,AA24,"") | AC24: =+IF(X24<>"","TM/CK","")
... T797: =+O797/1.08 -> 0 | U797: =+T797*N797 -> 0 | V797: =+SUMIF(B:B,B797,U:U) -> 0 | W797: =+IF(V797=V796,"",V797) | X797: =+IF(W797<>0,W797,"") | Y797: =+IF(X797<>"",8,"") | Z797: =+IF(X797<>"","VND","") | AA797: =+IF(B797=B796,"",E797) | AB797: =+IF(AA797<>0,AA797,"") | AC797: =+IF(X797<>"","TM/CK","")

Sheet Sheet2
C1: Mã Khách Hàng | F1: #NAME? | G1: Tên HKD | H1: Địa Chỉ Mới
A2: -45001563 | B2: chú minh 034065001063 | C2: 45001563 | D2: #N/A | E2: #N/A | F2: 034065001063 | G2: NGUYỄN VĂN TIẾN | H2: Phường Trần Lãm, Tỉnh Hưng Yên, Việt Nam
A3: -4757667 | B3: St Dailymart xuất hđ Kim Long | C3: 4757667 | D3: Siêu Thị Daily Mart | E3: Xã Vũ Phúc, Thành Phố Thái Bình | F3: 1 | H3: #N/A
A4: -4757647 | B4: Thu Hiền xuất lâm hà | C4: 4757647 | D4: Thu Hiền | E4: xã Vũ Chính, tp Thái Bình | F4: 1 | H4: #N/A
A5: -4501963 | B5: Cty Tnhh Thái An | C5: 4501963 | D5: Cty Tnhh Thái An | E5: P. Bồ Xyên, Thái Bình | F5: 1 | H5: #N/A
A6: -4501910 | B6: Chị Hà | C6: 4501910 | D6: Chị Hà | E6: P. Bồ Xyên, Thái Bình | F6: 1 | H6: #N/A
A7: -4501453 | B7: Cô Duyên c | C7: 4501453 | D7: Chị Trang Anh | E7: Tiền Phong, Thái Bình | F7: 1 | H7: #N/A
A8: -4501361 | B8: Kim Tuyến xuất Nhật Minh | C8: 4501361 | D8: Chị Kim Tuyến | E8: Phú Xuân, Thái Bình | F8: 1 | H8: #N/A
A9: -4501133 | B9: Anh Chinh | C9: 4501133 | D9: Anh Chinh | E9: Nam Hồng, Tiền Hải | F9: 1 | H9: #N/A
A10: -4499783 | B10: Cường Dung | C10: 4499783 | D10: Cường Dung | E10: Vũ Lăng, Tiền Hải | F10: 1 | H10: #N/A
A11: 4501252 | B11: #NAME? | C11: 4501252 | D11: Chị Kim Anh | E11: P. Đề Thám, Thái Bình | F11: 1 | H11: #N/A
A12: : 4499860 | B12: #NAME? | C12: 4499860 | D12: #N/A | E12: #N/A | F12: 1 | H12: #N/A
A13: : 4500902 | B13: #NAME? | C13: 4500902 | D13: #N/A | E13: #N/A | F13: 1 | H13: #N/A
A14: : 4501067 | B14: #NAME? | C14: 4501067 | D14: #N/A | E14: #N/A | F14: 1 | H14: #N/A
A15: : CHTN_KX | B15: #NAME? | C15: 1 | D15: #N/A | E15: #N/A | F15: 1 | H15: #N/A
A16: quang độ_ | C16: #VALUE! | D16: #VALUE! | E16: #VALUE! | F16: 1 | H16: #N/A
A17: -4757649 | B17: Dũng Tin - 034088012403 | C17: 4757649 | D17: Dũng Tin | E17: xã Nam Trung, Tiền Hải | F17: 1001319383 | G17: CÔNG TY TNHH TMTH DŨNG TIN | H17: Thôn Ái Quốc, Xã Hưng Phú, Tỉnh Hưng Yên, Việt Nam
A18: -4501887 | B18: Chị Huyền -1000207101 cccd 001163033134 | C18: 4501887 | D18: Chị Huyền | E18: P. Bồ Xyên, Thái Bình | F18: 001163033134 | G18: Hoa Thị Huyền | H18: Kiốt 63, chợ Bo, Phường Thái Bình, Tỉnh Hưng Yên, Việt Nam
A19: -4499782 | B19: Thanh Đức -8076540994 cccd 001188004813 | C19: 4499782 | D19: Thanh Đức | E19: Vũ Lăng, Tiền Hải | F19: 001188004813 | G19: HỘ KINH DOANH NGUYỄN THỊ ĐỨC | H19: Xã Tiền Hải, Tỉnh Hưng Yên, Việt Nam
A20: -4500620 | B20: long định 001188026258 | C20: 4500620 | D20: Long Định | E20: Minh Tân, Kiến Xương | F20: 001188026258 | G20: HỘ KINH DOANH HOÀNG THỊ ĐỊNH | H20: Thôn Tân Ấp, Xã Bình Thanh, Tỉnh Hưng Yên, Việt Nam
A21: -4499692 | B21: Hùng An Vũ Trung ( MST : 008167000036 | C21: 4499692 | D21: Hùng An | E21: Vũ Trung, Kiến Xương | F21: 008167000036 | G21: Vũ Thị Gái | H21: Xã Vũ Quý, Tỉnh Hưng Yên, Việt Nam
A22: -4500813 | B22: cty Nhiệt Điện- 0100100079-012 | C22: 4500813 | D22: Chị An Thùy | E22: Thụy Sơn, Thái Thụy | F22: 0100100079012 | H22: #N/A
A23: -4757668 | B23: goodex mart(027198007080) mst 0111127636 | C23: 4757668 | D23: Cửa hàng Goodex Mart | E23: Xã Tây Giang, huyện Tiền Hải | F23: 0111127636 | G23: CÔNG TY TNHH THƯƠNG MẠI VÀ DỊCH VỤ TỔNG HỢP GOODEX VIỆT NAM | H23: số 3 ngách 8 ngõ 313 đường Lĩnh Nam, Phường Vĩnh Tuy, Thành phố Hà Nội, Việt Nam
A24: -4499997 | B24: Nhung Trần Khánh Dư 014170000084 | C24: 4499997 | D24: Chị Nhung | E24: P. Bồ Xyên, Thái Bình | F24: 014170000084 | G24: Trương Thị Nhung | H24: Số 99, Phố Trần Khánh Dư, Phường Thái Bình, Tỉnh Hưng Yên, Việt Nam
A25: CHTN_TH - | B25: THắNG HƯƠNG (ĐÔNG TRà)017185004956 | C25: 1 | D25: #N/A | E25: #N/A | F25: 017185004956 | G25: PHạM THị HƯƠNG | H25: Xã Đông Tiền Hải, Tỉnh Hưng Yên , Việt Nam
A26: -4501574 | B26: toản tâm 8832645445 cccd 019186000464 | C26: 4501574 | D26: Chị Toản Tâm | E26: Vũ An, Kiến Xương | F26: 019186000464 | G26: HỘ KINH DOANH TẠP HÓA - TOẢN TÂM | H26: Xã Vũ Quý, Tỉnh Hưng Yên, Việt Nam
A27: -4994025 | B27: ánh Sang Cầu Báng 020188003724 | C27: 4994025 | D27: CH ánh Sang | E27: Tân Bình, Tp.Thái Bình | F27: 020188003724 | G27: HỘ KINH DOANH ÁNH SANG | H27: Tổ dân phố Đồng Thanh,Phường Thái Bình, Tỉnh Hưng Yên, Việt Nam
A28: -4501506 | B28: Tuấn Hùng Vũ Quý ( MST : 022162006168) | C28: 4501506 | D28: Anh Tuấn Hùng | E28: Vũ Quí, Kiến Xương | F28: 022162006168 | H28: #N/A
A29: -4501256 | B29: chị thành vinh(024183000450) | C29: 4501256 | D29: Chị Sen | E29: Đông Hoàng, Tiền Hải | F29: 024183000450 | G29: Nguyễn Thị Dũng | H29: Thôn Đông Hoàng, Xã Đồng Châu, Tỉnh Hưng Yên, Việt Nam
A30: -4499569 | B30: Vân Xô - 024190008236 | C30: 4499569 | D30: Vân Xô | E30: Đông Trung, Tiền Hải | F30: 024190008236 | G30: Ngô Thị Vân | H30: Xã Đồng Châu, Tỉnh Hưng Yên, Việt Nam
A31: -4501585 | B31: Phong Linh Bình Nguyên ( MST : 025180000909 | C31: 4501585 | D31: Phong Linh | E31: Thanh Tân, Kiến Xương | F31: 025180000909 | G31: Trịnh Thùy Linh | H31: Xã Bình Nguyên, Tỉnh Hưng Yên, Việt Nam | I31: Thôn Quân Hành, Tỉnh Hưng Yên
A32: -4501298 | B32: Huyền Oai cccd 025187015167 | C32: 4501298 | D32: Huyền Oai | E32: Thụy Duyên, Thái Thụy | F32: 025187015167 | G32: HỘ KINH DOANH HUYỀN OAI | H32: Thôn Hóa Tài, Xã Nam Thụy Anh, Tỉnh Hưng Yên, Việt Nam
A33: -4500146 | B33: Thu cúc ( MST : 027185012555) | C33: 4500146 | D33: chị thu cúc | E33: Thanh Tân, Kiến Xương | F33: 027185012555 | G33: Nguyễn Thị Cúc | H33: Xã Quang Lịch, Tỉnh Hưng Yên, Việt Nam
A34: -4501332 | B34: Dung Tân Bình 027188000154 | C34: 4501332 | D34: Chị Dung | E34: Tân Bình, Thái Bình | F34: 027188000154 | G34: Nguyễn Thuỳ Dung | H34: Phường Thái Bình, Tỉnh Hưng Yên, Việt Nam
A35: -4500208 | B35: Thu Hưng -8286398222 cccd 030171021155 | C35: 4500208 | D35: Thu Hưng | E35: Tân Bình, Thái Bình | F35: 030171021155 | G35: Phạm Thị Hương | H35: Thôn Dinh, Phường Thái Bình, Tỉnh Hưng Yên, Việt Nam
A36: -4500606 | B36: Cô Giáp - 0303443233 | C36: 4500606 | D36: Cô Giáp | E36: Thái Nguyên, Thái Thụy | F36: 0303443233 | G36: CÔNG TY CỔ PHẦN XÂY DỰNG COTECCONS | H36: 236/6 Điện Biên Phủ, Phường Gia Định, Thành phố Hồ Chí Minh, Việt Nam
A37: -4501291 | B37: Chị Mỵ 1001164764-001 cccd 031181003094 | C37: 4501291 | D37: Chị Mỵ | E37: Thái Giang, Thái Thụy | F37: 031181003094 | G37: HỘ KINH DOANH PHẠM THÚY MỴ | H37: Thôn Nha, Xã Tây Thái Ninh, Tỉnh Hưng Yên, Việt Nam
A38: -4501173 | B38: hiệu duyên- 8028653532-001 cccd 031187013376 | C38: 4501173 | D38: Chị Hiệu Duyên | E38: Thái Hưng, Thái Thụy | F38: 031187013376 | G38: Đỗ Thị Duyên | H38: Xã Thái Ninh, Tỉnh Hưng Yên, Việt Nam
A39: -4499375 | B39: Teen teen - 8847818228-001 cccd 034307015104- lê thị lan anh 031188002643 mới 031188002643 | C39: 4499375 | D39: Teen Teen | E39: Tây Giang, Tiền Hải | F39: 031188002643 | G39: HỘ KINH DOANH BÙI THỊ HOA | H39: Thôn Đông, Xã Ái Quốc, Tỉnh Hưng Yên, Việt Nam
A40: -4501333 | B40: CH Nam Thành 031190015134 | C40: 4501333 | D40: Chị Thanh | E40: Thụy An, Thái Thụy | F40: 031190015134 | G40: Vũ Thị Huyền | H40: Xã Đông Thuỵ Anh, Tỉnh Hưng Yên, Việt Nam
...

Sheet Sheet3
A3: Danh mục hàng hóa - vật tư
A5: Mã vật tư | B5: Tên vật tư | C5: Đvt
A6: 21006988 | B6: P/S Kem đánh răng Trẻ em hương dâu 35g/120 ống | C6: ống
A7: 21112984 | B7: LIFEBUOY DG TOC MEM MUOT 720X6G | C7: DÂY
A8: 21112986 | B8: LIFEBUOY Dầu gội Tóc dày óng ả 6gx12/60 dây | C8: Dây
A9: 21126131 | B9: LIFEBUOY NRT VUOT TROI RE0115 3X4KG | C9: Chai
A10: 21182542 | B10: LIPTON YELLOW LABEL SIP2 36X100X2G | C10: Hộp
A11: 32008713 | B11: SUNSILK DG vàng mền mượt diệu kỳ 6gx12/60 dây - T04/16 | C11: Dây
A12: 32008812 | B12: SUNSILK DG đen óng Mượt rạng ngời 6gx12/60 dây - T04/16 | C12: Dây
A13: 32008873 | B13: DOVE dầu gội Phục Hồi Hư Tổn 6gx12/60 Day -T01/16 | C13: Dây
A14: 62674330 | B14: SUNLIGHT LAU KINH SNHANH RE0123 12X520ML | C14: chai
A15: 62674331 | B15: SUNLIGHT NATURE KITCHEN RE0123 12X500ML | C15: chai
A16: 62674332 | B16: SUNLIGHT NTR MTPURPOSE RE0123 12X500ML | C16: chai
A17: 62674377 | B17: DOVE HC IN RPR/SG BLSM 8(1+1)610G/200G | C17: chai
... A191: 64323981 | B191: DOVE Dầu gội phục hồi tóc hư tổn 640g/8 chai | C191: chai
A192: 64323981A | B192: DOVE Dầu gội phục hồi tóc hư tổn 640g/8chai | C192: chai
A193: 64323983 | B193: DOVE Dầu Gội Phục Hồi Tóc Hư Tổn 640g/12 Túi | C193: túi
A194: 64323985 | B194: DOVE Dầu gội phục hồi tóc hư tổn 880g/8 chai | C194: chai
A195: 64323987 | B195: DOVE Dầu gội Phục Hồi Hư Tổn 1400g/6 chai | C195: chai
A196: 64323994 | B196: DOVE Dầu gội ngăn gãy rụng tóc 325g/12 chai | C196: chai
A197: 64323996 | B197: DOVE Dầu gội ngăn gãy rụng tóc 640g/8 chai | C197: chai
A198: 64323996A | B198: DOVE Dầu gội ngăn gãy rụng tóc 640g/8 chai | C198: chai
A199: 64323998 | B199: DOVE Dầu gội ngăn gãy rụng tóc 880g/8 chai | C199: chai
A200: 64324002 | B200: DOVE Kem Xả Ngăn Gãy Rụng Tóc 610g/8 Chai | C200: chai
A201: 64324004 | B201: DOVE Dầu gội dưỡng tóc bồng bềnh 640g/8 chai | C201: chai
A202: 64324006 | B202: DOVE Dầu gội hoa sen óng mềm 640gr/8 chai | C202: chai
A203: 64324008 | B203: Dove kem xả óng mềm tự nhiên 610g/8 chai | C203: Chai
A204: 64324010 | B204: Dove dầu gội vào nếp sống động tự nhiên 640g/8 chai | C204: Chai
A205: 64324012 | B205: DOVE dầu gội matcha & hoa anh đào 640g/8chai | C205: chai
A206: 64324016 | B206: DOVE Kem Xả Phục Hồi Hư Tổn 1 Phút Siêu Dưỡng 170g/24 Tuýp | C206: tuyp
A207: 64324018 | B207: DOVE Kem Xả Phục Hồi Hư Tổn 1 Phút Siêu Dưỡng 320g/12 Tuýp | C207: tuyp
A208: 64324020 | B208: DOVE Kem Xả Ngăn Gãy Rụng Tóc 320g/12 Tuýp | C208: tuyp
A209: 64324050 | B209: DOVE Kem xả phục hồi hư tổn 610g/8 chai | C209: chai
A210: 64324307 | B210: DOVE Kem ủ phục hồi hư tổn CERAMIDE 300ml/12 hũ | C210: hũ
... A222: 64330142 | B222: SUNLIGHT NRC Thiên Nhiên Lô Hội 2kg/4 Túi | C222: túi
A223: 64330142A | B223: SUNLIGHT NRC Thiên Nhiên Muối Khoáng và Lô Hội 2kg/4 túi | C223: Túi
A224: 64330144 | B224: SUNLIGHT NRC Trà Xanh 400g/24 Chai | C224: chai
A225: 64330146 | B225: SUNLIGHT NRC Trà Xanh 750g/15 chai | C225: chai
A226: 64330148 | B226: SUNLIGHT NRC Trà Xanh 3.5kg/3 Can | C226: can
A227: 64330150 | B227: SUNLIGHT NRC Trà Xanh 720g/18 Túi | C227: túi
...
